[2025-02-18T14:21:33.107+0000] {local_task_job_runner.py:123} INFO - ::group::Pre task execution logs
[2025-02-18T14:21:33.122+0000] {taskinstance.py:2613} INFO - Dependencies all met for dep_context=non-requeueable deps ti=<TaskInstance: kafka_streaming_process_pipeline.batch_processor manual__2025-02-18T14:21:32.294696+00:00 [queued]>
[2025-02-18T14:21:33.129+0000] {taskinstance.py:2613} INFO - Dependencies all met for dep_context=requeueable deps ti=<TaskInstance: kafka_streaming_process_pipeline.batch_processor manual__2025-02-18T14:21:32.294696+00:00 [queued]>
[2025-02-18T14:21:33.129+0000] {taskinstance.py:2866} INFO - Starting attempt 1 of 1
[2025-02-18T14:21:33.142+0000] {taskinstance.py:2889} INFO - Executing <Task(BashOperator): batch_processor> on 2025-02-18 14:21:32.294696+00:00
[2025-02-18T14:21:33.149+0000] {standard_task_runner.py:104} INFO - Running: ['***', 'tasks', 'run', 'kafka_streaming_process_pipeline', 'batch_processor', 'manual__2025-02-18T14:21:32.294696+00:00', '--job-id', '104', '--raw', '--subdir', 'DAGS_FOLDER/kafka_streaming_process.py', '--cfg-path', '/tmp/tmp_xirkqcj']
[2025-02-18T14:21:33.152+0000] {standard_task_runner.py:105} INFO - Job 104: Subtask batch_processor
[2025-02-18T14:21:33.152+0000] {logging_mixin.py:190} WARNING - /home/***/.local/lib/python3.12/site-packages/***/task/task_runner/standard_task_runner.py:70 DeprecationWarning: This process (pid=199) is multi-threaded, use of fork() may lead to deadlocks in the child.
[2025-02-18T14:21:33.153+0000] {standard_task_runner.py:72} INFO - Started process 201 to run task
[2025-02-18T14:21:33.187+0000] {task_command.py:467} INFO - Running <TaskInstance: kafka_streaming_process_pipeline.batch_processor manual__2025-02-18T14:21:32.294696+00:00 [running]> on host 944871224fc0
[2025-02-18T14:21:33.262+0000] {taskinstance.py:3132} INFO - Exporting env vars: AIRFLOW_CTX_DAG_OWNER='***' AIRFLOW_CTX_DAG_ID='kafka_streaming_process_pipeline' AIRFLOW_CTX_TASK_ID='batch_processor' AIRFLOW_CTX_EXECUTION_DATE='2025-02-18T14:21:32.294696+00:00' AIRFLOW_CTX_TRY_NUMBER='1' AIRFLOW_CTX_DAG_RUN_ID='manual__2025-02-18T14:21:32.294696+00:00'
[2025-02-18T14:21:33.263+0000] {taskinstance.py:731} INFO - ::endgroup::
[2025-02-18T14:21:33.281+0000] {subprocess.py:78} INFO - Tmp dir root location: /tmp
[2025-02-18T14:21:33.283+0000] {subprocess.py:88} INFO - Running command: ['/usr/bin/bash', '-c', 'python3 /usr/local/app/services/spark_batch_processor.py']
[2025-02-18T14:21:33.290+0000] {subprocess.py:99} INFO - Output:
[2025-02-18T14:21:35.117+0000] {subprocess.py:106} INFO - Traceback (most recent call last):
[2025-02-18T14:21:35.117+0000] {subprocess.py:106} INFO -   File "/usr/local/app/services/spark_batch_processor.py", line 11, in <module>
[2025-02-18T14:21:35.118+0000] {subprocess.py:106} INFO -     from UserEvents import MovieCatalogEvent
[2025-02-18T14:21:35.119+0000] {subprocess.py:106} INFO - ModuleNotFoundError: No module named 'UserEvents'
[2025-02-18T14:21:35.280+0000] {subprocess.py:110} INFO - Command exited with return code 1
[2025-02-18T14:21:35.292+0000] {taskinstance.py:3311} ERROR - Task failed with exception
Traceback (most recent call last):
  File "/home/airflow/.local/lib/python3.12/site-packages/airflow/models/taskinstance.py", line 767, in _execute_task
    result = _execute_callable(context=context, **execute_callable_kwargs)
             ^^^^^^^^^^^^^^^^^^^^^^^^^^^^^^^^^^^^^^^^^^^^^^^^^^^^^^^^^^^^^
  File "/home/airflow/.local/lib/python3.12/site-packages/airflow/models/taskinstance.py", line 733, in _execute_callable
    return ExecutionCallableRunner(
           ^^^^^^^^^^^^^^^^^^^^^^^^
  File "/home/airflow/.local/lib/python3.12/site-packages/airflow/utils/operator_helpers.py", line 252, in run
    return self.func(*args, **kwargs)
           ^^^^^^^^^^^^^^^^^^^^^^^^^^
  File "/home/airflow/.local/lib/python3.12/site-packages/airflow/models/baseoperator.py", line 422, in wrapper
    return func(self, *args, **kwargs)
           ^^^^^^^^^^^^^^^^^^^^^^^^^^^
  File "/home/airflow/.local/lib/python3.12/site-packages/airflow/operators/bash.py", line 276, in execute
    raise AirflowException(
airflow.exceptions.AirflowException: Bash command failed. The command returned a non-zero exit code 1.
[2025-02-18T14:21:35.300+0000] {taskinstance.py:1225} INFO - Marking task as FAILED. dag_id=kafka_streaming_process_pipeline, task_id=batch_processor, run_id=manual__2025-02-18T14:21:32.294696+00:00, execution_date=20250218T142132, start_date=20250218T142133, end_date=20250218T142135
[2025-02-18T14:21:35.335+0000] {taskinstance.py:340} INFO - ::group::Post task execution logs
[2025-02-18T14:21:35.336+0000] {standard_task_runner.py:124} ERROR - Failed to execute job 104 for task batch_processor (Bash command failed. The command returned a non-zero exit code 1.; 201)
Traceback (most recent call last):
  File "/home/airflow/.local/lib/python3.12/site-packages/airflow/task/task_runner/standard_task_runner.py", line 117, in _start_by_fork
    ret = args.func(args, dag=self.dag)
          ^^^^^^^^^^^^^^^^^^^^^^^^^^^^^
  File "/home/airflow/.local/lib/python3.12/site-packages/airflow/cli/cli_config.py", line 49, in command
    return func(*args, **kwargs)
           ^^^^^^^^^^^^^^^^^^^^^
  File "/home/airflow/.local/lib/python3.12/site-packages/airflow/utils/cli.py", line 116, in wrapper
    return f(*args, **kwargs)
           ^^^^^^^^^^^^^^^^^^
  File "/home/airflow/.local/lib/python3.12/site-packages/airflow/cli/commands/task_command.py", line 483, in task_run
    task_return_code = _run_task_by_selected_method(args, _dag, ti)
                       ^^^^^^^^^^^^^^^^^^^^^^^^^^^^^^^^^^^^^^^^^^^^
  File "/home/airflow/.local/lib/python3.12/site-packages/airflow/cli/commands/task_command.py", line 256, in _run_task_by_selected_method
    return _run_raw_task(args, ti)
           ^^^^^^^^^^^^^^^^^^^^^^^
  File "/home/airflow/.local/lib/python3.12/site-packages/airflow/cli/commands/task_command.py", line 341, in _run_raw_task
    return ti._run_raw_task(
           ^^^^^^^^^^^^^^^^^
  File "/home/airflow/.local/lib/python3.12/site-packages/airflow/utils/session.py", line 97, in wrapper
    return func(*args, session=session, **kwargs)
           ^^^^^^^^^^^^^^^^^^^^^^^^^^^^^^^^^^^^^^
  File "/home/airflow/.local/lib/python3.12/site-packages/airflow/models/taskinstance.py", line 3005, in _run_raw_task
    return _run_raw_task(
           ^^^^^^^^^^^^^^
  File "/home/airflow/.local/lib/python3.12/site-packages/airflow/models/taskinstance.py", line 273, in _run_raw_task
    TaskInstance._execute_task_with_callbacks(
  File "/home/airflow/.local/lib/python3.12/site-packages/airflow/models/taskinstance.py", line 3159, in _execute_task_with_callbacks
    result = self._execute_task(context, task_orig)
             ^^^^^^^^^^^^^^^^^^^^^^^^^^^^^^^^^^^^^^
  File "/home/airflow/.local/lib/python3.12/site-packages/airflow/models/taskinstance.py", line 3183, in _execute_task
    return _execute_task(self, context, task_orig)
           ^^^^^^^^^^^^^^^^^^^^^^^^^^^^^^^^^^^^^^^
  File "/home/airflow/.local/lib/python3.12/site-packages/airflow/models/taskinstance.py", line 767, in _execute_task
    result = _execute_callable(context=context, **execute_callable_kwargs)
             ^^^^^^^^^^^^^^^^^^^^^^^^^^^^^^^^^^^^^^^^^^^^^^^^^^^^^^^^^^^^^
  File "/home/airflow/.local/lib/python3.12/site-packages/airflow/models/taskinstance.py", line 733, in _execute_callable
    return ExecutionCallableRunner(
           ^^^^^^^^^^^^^^^^^^^^^^^^
  File "/home/airflow/.local/lib/python3.12/site-packages/airflow/utils/operator_helpers.py", line 252, in run
    return self.func(*args, **kwargs)
           ^^^^^^^^^^^^^^^^^^^^^^^^^^
  File "/home/airflow/.local/lib/python3.12/site-packages/airflow/models/baseoperator.py", line 422, in wrapper
    return func(self, *args, **kwargs)
           ^^^^^^^^^^^^^^^^^^^^^^^^^^^
  File "/home/airflow/.local/lib/python3.12/site-packages/airflow/operators/bash.py", line 276, in execute
    raise AirflowException(
airflow.exceptions.AirflowException: Bash command failed. The command returned a non-zero exit code 1.
[2025-02-18T14:21:35.373+0000] {local_task_job_runner.py:266} INFO - Task exited with return code 1
[2025-02-18T14:21:35.385+0000] {taskinstance.py:3895} INFO - 0 downstream tasks scheduled from follow-on schedule check
[2025-02-18T14:21:35.387+0000] {local_task_job_runner.py:245} INFO - ::endgroup::
