[2025-02-17T15:09:01.274+0000] {local_task_job_runner.py:123} INFO - ::group::Pre task execution logs
[2025-02-17T15:09:01.285+0000] {taskinstance.py:2613} INFO - Dependencies all met for dep_context=non-requeueable deps ti=<TaskInstance: kafka_streaming_process_pipeline.start_user_activity_kafka_producers manual__2025-02-17T15:08:44.383579+00:00 [queued]>
[2025-02-17T15:09:01.291+0000] {taskinstance.py:2613} INFO - Dependencies all met for dep_context=requeueable deps ti=<TaskInstance: kafka_streaming_process_pipeline.start_user_activity_kafka_producers manual__2025-02-17T15:08:44.383579+00:00 [queued]>
[2025-02-17T15:09:01.294+0000] {taskinstance.py:2866} INFO - Starting attempt 1 of 1
[2025-02-17T15:09:01.306+0000] {taskinstance.py:2889} INFO - Executing <Task(BashOperator): start_user_activity_kafka_producers> on 2025-02-17 15:08:44.383579+00:00
[2025-02-17T15:09:01.312+0000] {standard_task_runner.py:104} INFO - Running: ['***', 'tasks', 'run', 'kafka_streaming_process_pipeline', 'start_user_activity_kafka_producers', 'manual__2025-02-17T15:08:44.383579+00:00', '--job-id', '52', '--raw', '--subdir', 'DAGS_FOLDER/kafka_streaming_process.py', '--cfg-path', '/tmp/tmppwpmzo2h']
[2025-02-17T15:09:01.314+0000] {standard_task_runner.py:105} INFO - Job 52: Subtask start_user_activity_kafka_producers
[2025-02-17T15:09:01.314+0000] {logging_mixin.py:190} WARNING - /home/***/.local/lib/python3.12/site-packages/***/task/task_runner/standard_task_runner.py:70 DeprecationWarning: This process (pid=2721) is multi-threaded, use of fork() may lead to deadlocks in the child.
[2025-02-17T15:09:01.314+0000] {standard_task_runner.py:72} INFO - Started process 2723 to run task
[2025-02-17T15:09:01.346+0000] {task_command.py:467} INFO - Running <TaskInstance: kafka_streaming_process_pipeline.start_user_activity_kafka_producers manual__2025-02-17T15:08:44.383579+00:00 [running]> on host b6abba1bc830
[2025-02-17T15:09:01.406+0000] {taskinstance.py:3132} INFO - Exporting env vars: AIRFLOW_CTX_DAG_OWNER='***' AIRFLOW_CTX_DAG_ID='kafka_streaming_process_pipeline' AIRFLOW_CTX_TASK_ID='start_user_activity_kafka_producers' AIRFLOW_CTX_EXECUTION_DATE='2025-02-17T15:08:44.383579+00:00' AIRFLOW_CTX_TRY_NUMBER='1' AIRFLOW_CTX_DAG_RUN_ID='manual__2025-02-17T15:08:44.383579+00:00'
[2025-02-17T15:09:01.407+0000] {taskinstance.py:731} INFO - ::endgroup::
[2025-02-17T15:09:01.420+0000] {subprocess.py:78} INFO - Tmp dir root location: /tmp
[2025-02-17T15:09:01.421+0000] {subprocess.py:88} INFO - Running command: ['/usr/bin/bash', '-c', 'python3 /usr/local/app/kafka/UserActivitySimulator.py']
[2025-02-17T15:09:01.427+0000] {subprocess.py:99} INFO - Output:
[2025-02-17T15:09:02.381+0000] {subprocess.py:106} INFO - /home/***/.local/lib/python3.12/site-packages/pyspark/bin/load-spark-env.sh: line 68: ps: command not found
[2025-02-17T15:09:04.097+0000] {subprocess.py:106} INFO - Setting default log level to "WARN".
[2025-02-17T15:09:04.099+0000] {subprocess.py:106} INFO - To adjust logging level use sc.setLogLevel(newLevel). For SparkR, use setLogLevel(newLevel).
[2025-02-17T15:09:04.314+0000] {subprocess.py:106} INFO - 25/02/17 15:09:04 WARN NativeCodeLoader: Unable to load native-hadoop library for your platform... using builtin-java classes where applicable
[2025-02-17T15:09:04.979+0000] {subprocess.py:106} INFO - 25/02/17 15:09:04 WARN Utils: Service 'SparkUI' could not bind on port 4040. Attempting port 4041.
[2025-02-17T15:09:06.610+0000] {subprocess.py:106} INFO - %6|1739804946.610|GETSUBSCRIPTIONS|ccloud-python-client-d5d51593-8a8e-4679-b89e-7349479019ff#producer-1| [thrd:main]: Telemetry client instance id changed from AAAAAAAAAAAAAAAAAAAAAA to u3SxjTTdT6yv/esbidUY8g
[2025-02-17T15:09:07.416+0000] {subprocess.py:106} INFO - ERROR:root:Sent Avro message to topic checkout_to_cart_topic: b'\x00\x00\x01\x86\xa742025-02-17T15:09:05.434403 checkout_to_cart\n72858H180c9287-cd38-4664-ada0-fac1db271cbc\x08Cash'
[2025-02-17T15:09:08.404+0000] {subprocess.py:106} INFO - ERROR:root:Sent Avro message to topic checkout_to_cart_topic: b'\x00\x00\x01\x86\xa742025-02-17T15:09:07.416310 checkout_to_cart\n72858H95c40f4e-9d98-4c48-be97-3ae33731c66d\x08Card'
[2025-02-17T15:09:08.405+0000] {subprocess.py:106} INFO - Traceback (most recent call last):
[2025-02-17T15:09:08.405+0000] {subprocess.py:106} INFO -   File "/usr/local/app/kafka/UserActivitySimulator.py", line 85, in <module>
[2025-02-17T15:09:08.406+0000] {subprocess.py:106} INFO -     simulator.start_simulation()
[2025-02-17T15:09:08.406+0000] {subprocess.py:106} INFO -   File "/usr/local/app/kafka/UserActivitySimulator.py", line 71, in start_simulation
[2025-02-17T15:09:08.407+0000] {subprocess.py:106} INFO -     self.generate_event()
[2025-02-17T15:09:08.408+0000] {subprocess.py:106} INFO -   File "/usr/local/app/kafka/UserActivitySimulator.py", line 42, in generate_event
[2025-02-17T15:09:08.409+0000] {subprocess.py:106} INFO -     event = event_class() if callable(event_class) else event_class
[2025-02-17T15:09:08.409+0000] {subprocess.py:106} INFO -             ^^^^^^^^^^^^^
[2025-02-17T15:09:08.410+0000] {subprocess.py:106} INFO -   File "/usr/local/app/kafka/UserActivitySimulator.py", line 36, in <lambda>
[2025-02-17T15:09:08.410+0000] {subprocess.py:106} INFO -     lambda: ItemViewEvent(self.movies),
[2025-02-17T15:09:08.411+0000] {subprocess.py:106} INFO -                           ^^^^^^^^^^^
[2025-02-17T15:09:08.411+0000] {subprocess.py:106} INFO - AttributeError: 'UserActivitySimulator' object has no attribute 'movies'
[2025-02-17T15:09:08.455+0000] {subprocess.py:106} INFO - %4|1739804948.455|TERMINATE|ccloud-python-client-d5d51593-8a8e-4679-b89e-7349479019ff#producer-1| [thrd:app]: Producer terminating with 1 message (97 bytes) still in queue or transit: use flush() to wait for outstanding message delivery
[2025-02-17T15:09:08.892+0000] {subprocess.py:110} INFO - Command exited with return code 1
[2025-02-17T15:09:08.902+0000] {taskinstance.py:3311} ERROR - Task failed with exception
Traceback (most recent call last):
  File "/home/airflow/.local/lib/python3.12/site-packages/airflow/models/taskinstance.py", line 767, in _execute_task
    result = _execute_callable(context=context, **execute_callable_kwargs)
             ^^^^^^^^^^^^^^^^^^^^^^^^^^^^^^^^^^^^^^^^^^^^^^^^^^^^^^^^^^^^^
  File "/home/airflow/.local/lib/python3.12/site-packages/airflow/models/taskinstance.py", line 733, in _execute_callable
    return ExecutionCallableRunner(
           ^^^^^^^^^^^^^^^^^^^^^^^^
  File "/home/airflow/.local/lib/python3.12/site-packages/airflow/utils/operator_helpers.py", line 252, in run
    return self.func(*args, **kwargs)
           ^^^^^^^^^^^^^^^^^^^^^^^^^^
  File "/home/airflow/.local/lib/python3.12/site-packages/airflow/models/baseoperator.py", line 422, in wrapper
    return func(self, *args, **kwargs)
           ^^^^^^^^^^^^^^^^^^^^^^^^^^^
  File "/home/airflow/.local/lib/python3.12/site-packages/airflow/operators/bash.py", line 276, in execute
    raise AirflowException(
airflow.exceptions.AirflowException: Bash command failed. The command returned a non-zero exit code 1.
[2025-02-17T15:09:08.907+0000] {taskinstance.py:1225} INFO - Marking task as FAILED. dag_id=kafka_streaming_process_pipeline, task_id=start_user_activity_kafka_producers, run_id=manual__2025-02-17T15:08:44.383579+00:00, execution_date=20250217T150844, start_date=20250217T150901, end_date=20250217T150908
[2025-02-17T15:09:08.921+0000] {taskinstance.py:340} INFO - ::group::Post task execution logs
[2025-02-17T15:09:08.922+0000] {standard_task_runner.py:124} ERROR - Failed to execute job 52 for task start_user_activity_kafka_producers (Bash command failed. The command returned a non-zero exit code 1.; 2723)
Traceback (most recent call last):
  File "/home/airflow/.local/lib/python3.12/site-packages/airflow/task/task_runner/standard_task_runner.py", line 117, in _start_by_fork
    ret = args.func(args, dag=self.dag)
          ^^^^^^^^^^^^^^^^^^^^^^^^^^^^^
  File "/home/airflow/.local/lib/python3.12/site-packages/airflow/cli/cli_config.py", line 49, in command
    return func(*args, **kwargs)
           ^^^^^^^^^^^^^^^^^^^^^
  File "/home/airflow/.local/lib/python3.12/site-packages/airflow/utils/cli.py", line 116, in wrapper
    return f(*args, **kwargs)
           ^^^^^^^^^^^^^^^^^^
  File "/home/airflow/.local/lib/python3.12/site-packages/airflow/cli/commands/task_command.py", line 483, in task_run
    task_return_code = _run_task_by_selected_method(args, _dag, ti)
                       ^^^^^^^^^^^^^^^^^^^^^^^^^^^^^^^^^^^^^^^^^^^^
  File "/home/airflow/.local/lib/python3.12/site-packages/airflow/cli/commands/task_command.py", line 256, in _run_task_by_selected_method
    return _run_raw_task(args, ti)
           ^^^^^^^^^^^^^^^^^^^^^^^
  File "/home/airflow/.local/lib/python3.12/site-packages/airflow/cli/commands/task_command.py", line 341, in _run_raw_task
    return ti._run_raw_task(
           ^^^^^^^^^^^^^^^^^
  File "/home/airflow/.local/lib/python3.12/site-packages/airflow/utils/session.py", line 97, in wrapper
    return func(*args, session=session, **kwargs)
           ^^^^^^^^^^^^^^^^^^^^^^^^^^^^^^^^^^^^^^
  File "/home/airflow/.local/lib/python3.12/site-packages/airflow/models/taskinstance.py", line 3005, in _run_raw_task
    return _run_raw_task(
           ^^^^^^^^^^^^^^
  File "/home/airflow/.local/lib/python3.12/site-packages/airflow/models/taskinstance.py", line 273, in _run_raw_task
    TaskInstance._execute_task_with_callbacks(
  File "/home/airflow/.local/lib/python3.12/site-packages/airflow/models/taskinstance.py", line 3159, in _execute_task_with_callbacks
    result = self._execute_task(context, task_orig)
             ^^^^^^^^^^^^^^^^^^^^^^^^^^^^^^^^^^^^^^
  File "/home/airflow/.local/lib/python3.12/site-packages/airflow/models/taskinstance.py", line 3183, in _execute_task
    return _execute_task(self, context, task_orig)
           ^^^^^^^^^^^^^^^^^^^^^^^^^^^^^^^^^^^^^^^
  File "/home/airflow/.local/lib/python3.12/site-packages/airflow/models/taskinstance.py", line 767, in _execute_task
    result = _execute_callable(context=context, **execute_callable_kwargs)
             ^^^^^^^^^^^^^^^^^^^^^^^^^^^^^^^^^^^^^^^^^^^^^^^^^^^^^^^^^^^^^
  File "/home/airflow/.local/lib/python3.12/site-packages/airflow/models/taskinstance.py", line 733, in _execute_callable
    return ExecutionCallableRunner(
           ^^^^^^^^^^^^^^^^^^^^^^^^
  File "/home/airflow/.local/lib/python3.12/site-packages/airflow/utils/operator_helpers.py", line 252, in run
    return self.func(*args, **kwargs)
           ^^^^^^^^^^^^^^^^^^^^^^^^^^
  File "/home/airflow/.local/lib/python3.12/site-packages/airflow/models/baseoperator.py", line 422, in wrapper
    return func(self, *args, **kwargs)
           ^^^^^^^^^^^^^^^^^^^^^^^^^^^
  File "/home/airflow/.local/lib/python3.12/site-packages/airflow/operators/bash.py", line 276, in execute
    raise AirflowException(
airflow.exceptions.AirflowException: Bash command failed. The command returned a non-zero exit code 1.
[2025-02-17T15:09:08.948+0000] {local_task_job_runner.py:266} INFO - Task exited with return code 1
[2025-02-17T15:09:08.961+0000] {taskinstance.py:3895} INFO - 0 downstream tasks scheduled from follow-on schedule check
[2025-02-17T15:09:08.963+0000] {local_task_job_runner.py:245} INFO - ::endgroup::
